Workbook

Sheet 🏠 Dashboard
A1: 🏪 POS BUSINESS MANAGEMENT DASHBOARD
A4: Real-Time Business Analytics | Auto-Updated from All Sheets | Fiscal Year 2025
A6: 💵 TOTAL REVENUE | E6: 📈 TOTAL PROFIT | I6: 💸 TOTAL EXPENSES | M6: 🛒 TOTAL ORDERS | Q6: 👥 PAYROLL COST
A7: =SUM('📊 Sales Report'!I$5:I$957) -> 12972.736 | E7: =SUM('📊 Sales Report'!N$5:N$957) -> 5674.5 | I7: =SUM('💸 Expenses'!F$5:F$24) -> 113497 | M7: =COUNTA('📊 Sales Report'!B$5:B$957) -> 953 | Q7: =SUM('👥 Payroll'!I$5:I$12) -> 127546.88
A10: 📦 INVENTORY VALUE | E10: 🧾 AVG ORDER VALUE | I10: ⚠ OUTSTANDING PMTS | M10: 🔴 LOW STOCK ITEMS | Q10: 📋 VAT PAYABLE (YTD)
A11: =SUM('📦 Inventory'!K$5:K$19) -> 89765 | E11: =IFERROR(SUM('📊 Sales Report'!I$5:I$957)/COUNTA('📊 Sales Report'!B$5:B$957),0) -> 13.612525 | I11: =SUMIF('🚚 Suppliers'!H$5:H$19,"Pending",'🚚 Suppliers'!F$5:F$19) -> 26660 | M11: =COUNTIF('📦 Inventory'!J$5:J$19,"LOW STOCK") -> 3 | Q11: =SUM('📋 Tax & VAT'!F5:F16) -> -10770.457
A14: 💳 SALES BY PAYMENT METHOD | I14: 🥇 TOP SELLING PRODUCTS (by Revenue) | Q14: ⚠️ LOW STOCK ALERTS
A15: Payment Method | B15: Amount | C15: % Share | I15: Product | J15: Units Sold | K15: Revenue | Q15: Product | R15: Stock | S15: Min | T15: Status
A16: Cash | B16: =SUMIF('📊 Sales Report'!$J$5:$J$957,A16,'📊 Sales Report'!$I$5:$I$957) -> 2489.452 | C16: =IFERROR(B16/SUM($B$16:$B$20),0) -> 0.19189876 | I16: Espresso Coffee | J16: =SUMIF('📊 Sales Report'!$C$5:$C$957,I16,'📊 Sales Report'!$E$5:$E$957) -> 226 | K16: =SUMIF('📊 Sales Report'!$C$5:$C$957,I16,'📊 Sales Report'!$I$5:$I$957) -> 861.224
A17: GCash | B17: =SUMIF('📊 Sales Report'!$J$5:$J$957,A17,'📊 Sales Report'!$I$5:$I$957) -> 2500.4 | C17: =IFERROR(B17/SUM($B$16:$B$20),0) -> 0.19274269 | I17: Latte | J17: =SUMIF('📊 Sales Report'!$C$5:$C$957,I17,'📊 Sales Report'!$E$5:$E$957) -> 288 | K17: =SUMIF('📊 Sales Report'!$C$5:$C$957,I17,'📊 Sales Report'!$I$5:$I$957) -> 1402.128
A18: Credit Card | B18: =SUMIF('📊 Sales Report'!$J$5:$J$957,A18,'📊 Sales Report'!$I$5:$I$957) -> 2724.148 | C18: =IFERROR(B18/SUM($B$16:$B$20),0) -> 0.20999024 | I18: Croissant | J18: =SUMIF('📊 Sales Report'!$C$5:$C$957,I18,'📊 Sales Report'!$E$5:$E$957) -> 291 | K18: =SUMIF('📊 Sales Report'!$C$5:$C$957,I18,'📊 Sales Report'!$I$5:$I$957) -> 789.32 | Q18: Croissant (pcs) | R18: 8 | S18: 15 | T18: LOW
A19: Debit Card | B19: =SUMIF('📊 Sales Report'!$J$5:$J$957,A19,'📊 Sales Report'!$I$5:$I$957) -> 2860.872 | C19: =IFERROR(B19/SUM($B$16:$B$20),0) -> 0.22052958 | I19: Chocolate Cake | J19: =SUMIF('📊 Sales Report'!$C$5:$C$957,I19,'📊 Sales Report'!$E$5:$E$957) -> 282 | K19: =SUMIF('📊 Sales Report'!$C$5:$C$957,I19,'📊 Sales Report'!$I$5:$I$957) -> 1528.52
A20: PayMaya | B20: =SUMIF('📊 Sales Report'!$J$5:$J$957,A20,'📊 Sales Report'!$I$5:$I$957) -> 2397.864 | C20: =IFERROR(B20/SUM($B$16:$B$20),0) -> 0.18483873 | I20: Mineral Water | J20: =SUMIF('📊 Sales Report'!$C$5:$C$957,I20,'📊 Sales Report'!$E$5:$E$957) -> 327 | K20: =SUMIF('📊 Sales Report'!$C$5:$C$957,I20,'📊 Sales Report'!$I$5:$I$957) -> 533.568
I21: Fried Chicken | J21: =SUMIF('📊 Sales Report'!$C$5:$C$957,I21,'📊 Sales Report'!$E$5:$E$957) -> 260 | K21: =SUMIF('📊 Sales Report'!$C$5:$C$957,I21,'📊 Sales Report'!$I$5:$I$957) -> 2416.652
A22: 📅 MONTHLY SALES & PROFIT SUMMARY | K22: =SUMIF('📊 Sales Report'!$C$5:$C$957,I22,'📊 Sales Report'!$I$5:$I$957) -> 0 | L22: 🏆 TOP EMPLOYEE PERFORMANCE
A23: Month | B23: Orders | C23: Revenue | D23: COGS | E23: Gross Profit | F23: Expenses | G23: Net Profit | H23: Profit Margin | L23: Employee | M23: Sales | N23: Txns | O23: Avg Sale | P23: Score
A24: January | B24: =SUMPRODUCT((TEXT('📊 Sales Report'!$A$5:$A$957,"MMMM")=A24)*1) -> 334 | C24: =SUMPRODUCT((TEXT('📊 Sales Report'!$A$5:$A$957,"MMMM")=A24)*'📊 Sales Report'!$I$5:$I$957) -> 4610.06 | D24: =C24-SUMPRODUCT((TEXT('📊 Sales Report'!$A$5:$A$957,"MMMM")=A24)*'📊 Sales Report'!$N$5:$N$957) -> 2586.635 | E24: =SUMPRODUCT((TEXT('📊 Sales Report'!$A$5:$A$957,"MMMM")=A24)*'📊 Sales Report'!$N$5:$N$957) -> 2023.425 | F24: =SUMPRODUCT((TEXT('💸 Expenses'!$A$5:$A$24,"MMMM")=A24)*'💸 Expenses'!$F$5:$F$24) -> 40799 | G24: =E24-F24 -> -38775.575 | H24: =IFERROR(G24/C24,0) -> -8.4110782 | L24: =INDEX('🏆 Performance'!A$5:A$12,MATCH(LARGE('🏆 Performance'!G$5:G$12,1),'🏆 Performance'!G$5:G$12,0)) -> Juan Dela Cruz | M24: =INDEX('🏆 Performance'!B$5:B$12,MATCH(LARGE('🏆 Performance'!G$5:G$12,1),'🏆 Performance'!G$5:G$12,0)) -> 2721.768 | N24: =INDEX('🏆 Performance'!C$5:C$12,MATCH(LARGE('🏆 Performance'!G$5:G$12,1),'🏆 Performance'!G$5:G$12,0)) -> 205 | O24: =INDEX('🏆 Performance'!D$5:D$12,MATCH(LARGE('🏆 Performance'!G$5:G$12,1),'🏆 Performance'!G$5:G$12,0)) -> 13.276917 | P24: =LARGE('🏆 Performance'!G$5:G$12,1) -> 95.2 | Q24: Sandwich Bread (loaf) | R24: 12 | S24: 20 | T24: LOW
A25: February | B25: =SUMPRODUCT((TEXT('📊 Sales Report'!$A$5:$A$957,"MMMM")=A25)*1) -> 288 | C25: =SUMPRODUCT((TEXT('📊 Sales Report'!$A$5:$A$957,"MMMM")=A25)*'📊 Sales Report'!$I$5:$I$957) -> 3866.912 | D25: =C25-SUMPRODUCT((TEXT('📊 Sales Report'!$A$5:$A$957,"MMMM")=A25)*'📊 Sales Report'!$N$5:$N$957) -> 2190.412 | E25: =SUMPRODUCT((TEXT('📊 Sales Report'!$A$5:$A$957,"MMMM")=A25)*'📊 Sales Report'!$N$5:$N$957) -> 1676.5 | F25: =SUMPRODUCT((TEXT('💸 Expenses'!$A$5:$A$24,"MMMM")=A25)*'💸 Expenses'!$F$5:$F$24) -> 36049 | G25: =E25-F25 -> -34372.5 | H25: =IFERROR(G25/C25,0) -> -8.8888757 | L25: =INDEX('🏆 Performance'!A$5:A$12,MATCH(LARGE('🏆 Performance'!G$5:G$12,2),'🏆 Performance'!G$5:G$12,0)) -> Lisa Tan | M25: =INDEX('🏆 Performance'!B$5:B$12,MATCH(LARGE('🏆 Performance'!G$5:G$12,2),'🏆 Performance'!G$5:G$12,0)) -> 2501.632 | N25: =INDEX('🏆 Performance'!C$5:C$12,MATCH(LARGE('🏆 Performance'!G$5:G$12,2),'🏆 Performance'!G$5:G$12,0)) -> 188 | O25: =INDEX('🏆 Performance'!D$5:D$12,MATCH(LARGE('🏆 Performance'!G$5:G$12,2),'🏆 Performance'!G$5:G$12,0)) -> 13.306553 | P25: =LARGE('🏆 Performance'!G$5:G$12,2) -> 93.7
A26: March | B26: =SUMPRODUCT((TEXT('📊 Sales Report'!$A$5:$A$957,"MMMM")=A26)*1) -> 331 | C26: =SUMPRODUCT((TEXT('📊 Sales Report'!$A$5:$A$957,"MMMM")=A26)*'📊 Sales Report'!$I$5:$I$957) -> 4495.764 | D26: =C26-SUMPRODUCT((TEXT('📊 Sales Report'!$A$5:$A$957,"MMMM")=A26)*'📊 Sales Report'!$N$5:$N$957) -> 2521.189 | E26: =SUMPRODUCT((TEXT('📊 Sales Report'!$A$5:$A$957,"MMMM")=A26)*'📊 Sales Report'!$N$5:$N$957) -> 1974.575 | F26: =SUMPRODUCT((TEXT('💸 Expenses'!$A$5:$A$24,"MMMM")=A26)*'💸 Expenses'!$F$5:$F$24) -> 36649 | G26: =E26-F26 -> -34674.425 | H26: =IFERROR(G26/C26,0) -> -7.712688 | L26: =INDEX('🏆 Performance'!A$5:A$12,MATCH(LARGE('🏆 Performance'!G$5:G$12,3),'🏆 Performance'!G$5:G$12,0)) -> Ana Reyes | M26: =INDEX('🏆 Performance'!B$5:B$12,MATCH(LARGE('🏆 Performance'!G$5:G$12,3),'🏆 Performance'!G$5:G$12,0)) -> 2649.668 | N26: =INDEX('🏆 Performance'!C$5:C$12,MATCH(LARGE('🏆 Performance'!G$5:G$12,3),'🏆 Performance'!G$5:G$12,0)) -> 191 | O26: =INDEX('🏆 Performance'!D$5:D$12,MATCH(LARGE('🏆 Performance'!G$5:G$12,3),'🏆 Performance'!G$5:G$12,0)) -> 13.872607 | P26: =LARGE('🏆 Performance'!G$5:G$12,3) -> 92.7
A27: April | B27: =SUMPRODUCT((TEXT('📊 Sales Report'!$A$5:$A$957,"MMMM")=A27)*1) -> 0 | C27: =SUMPRODUCT((TEXT('📊 Sales Report'!$A$5:$A$957,"MMMM")=A27)*'📊 Sales Report'!$I$5:$I$957) -> 0 | D27: =C27-SUMPRODUCT((TEXT('📊 Sales Report'!$A$5:$A$957,"MMMM")=A27)*'📊 Sales Report'!$N$5:$N$957) -> 0 | E27: =SUMPRODUCT((TEXT('📊 Sales Report'!$A$5:$A$957,"MMMM")=A27)*'📊 Sales Report'!$N$5:$N$957) -> 0 | F27: =SUMPRODUCT((TEXT('💸 Expenses'!$A$5:$A$24,"MMMM")=A27)*'💸 Expenses'!$F$5:$F$24) -> 0 | G27: =E27-F27 -> 0 | H27: =IFERROR(G27/C27,0) -> 0 | L27: =INDEX('🏆 Performance'!A$5:A$12,MATCH(LARGE('🏆 Performance'!G$5:G$12,4),'🏆 Performance'!G$5:G$12,0)) -> Carlo Bautista | M27: =INDEX('🏆 Performance'!B$5:B$12,MATCH(LARGE('🏆 Performance'!G$5:G$12,4),'🏆 Performance'!G$5:G$12,0)) -> 2451.792 | N27: =INDEX('🏆 Performance'!C$5:C$12,MATCH(LARGE('🏆 Performance'!G$5:G$12,4),'🏆 Performance'!G$5:G$12,0)) -> 186 | O27: =INDEX('🏆 Performance'!D$5:D$12,MATCH(LARGE('🏆 Performance'!G$5:G$12,4),'🏆 Performance'!G$5:G$12,0)) -> 13.181677 | P27: =LARGE('🏆 Performance'!G$5:G$12,4) -> 91.5
A28: May | B28: =SUMPRODUCT((TEXT('📊 Sales Report'!$A$5:$A$957,"MMMM")=A28)*1) -> 0 | C28: =SUMPRODUCT((TEXT('📊 Sales Report'!$A$5:$A$957,"MMMM")=A28)*'📊 Sales Report'!$I$5:$I$957) -> 0 | D28: =C28-SUMPRODUCT((TEXT('📊 Sales Report'!$A$5:$A$957,"MMMM")=A28)*'📊 Sales Report'!$N$5:$N$957) -> 0 | E28: =SUMPRODUCT((TEXT('📊 Sales Report'!$A$5:$A$957,"MMMM")=A28)*'📊 Sales Report'!$N$5:$N$957) -> 0 | F28: =SUMPRODUCT((TEXT('💸 Expenses'!$A$5:$A$24,"MMMM")=A28)*'💸 Expenses'!$F$5:$F$24) -> 0 | G28: =E28-F28 -> 0 | H28: =IFERROR(G28/C28,0) -> 0 | L28: =INDEX('🏆 Performance'!A$5:A$12,MATCH(LARGE('🏆 Performance'!G$5:G$12,5),'🏆 Performance'!G$5:G$12,0)) -> Maria Santos | M28: =INDEX('🏆 Performance'!B$5:B$12,MATCH(LARGE('🏆 Performance'!G$5:G$12,5),'🏆 Performance'!G$5:G$12,0)) -> 2647.876 | N28: =INDEX('🏆 Performance'!C$5:C$12,MATCH(LARGE('🏆 Performance'!G$5:G$12,5),'🏆 Performance'!G$5:G$12,0)) -> 183 | O28: =INDEX('🏆 Performance'!D$5:D$12,MATCH(LARGE('🏆 Performance'!G$5:G$12,5),'🏆 Performance'!G$5:G$12,0)) -> 14.469268 | P28: =LARGE('🏆 Performance'!G$5:G$12,5) -> 90.9 | Q28: Disposable Cup (100pcs | R28: 7 | S28: 20 | T28: LOW
A29: June | B29: =SUMPRODUCT((TEXT('📊 Sales Report'!$A$5:$A$957,"MMMM")=A29)*1) -> 0 | C29: =SUMPRODUCT((TEXT('📊 Sales Report'!$A$5:$A$957,"MMMM")=A29)*'📊 Sales Report'!$I$5:$I$957) -> 0 | D29: =C29-SUMPRODUCT((TEXT('📊 Sales Report'!$A$5:$A$957,"MMMM")=A29)*'📊 Sales Report'!$N$5:$N$957) -> 0 | E29: =SUMPRODUCT((TEXT('📊 Sales Report'!$A$5:$A$957,"MMMM")=A29)*'📊 Sales Report'!$N$5:$N$957) -> 0 | F29: =SUMPRODUCT((TEXT('💸 Expenses'!$A$5:$A$24,"MMMM")=A29)*'💸 Expenses'!$F$5:$F$24) -> 0 | G29: =E29-F29 -> 0 | H29: =IFERROR(G29/C29,0) -> 0 | L29: =INDEX('🏆 Performance'!A$5:A$12,MATCH(LARGE('🏆 Performance'!G$5:G$12,6),'🏆 Performance'!G$5:G$12,0)) -> Roberto Mendoza | M29: =INDEX('🏆 Performance'!B$5:B$12,MATCH(LARGE('🏆 Performance'!G$5:G$12,6),'🏆 Performance'!G$5:G$12,0)) -> 0 | N29: =INDEX('🏆 Performance'!C$5:C$12,MATCH(LARGE('🏆 Performance'!G$5:G$12,6),'🏆 Performance'!G$5:G$12,0)) -> 0 | O29: =INDEX('🏆 Performance'!D$5:D$12,MATCH(LARGE('🏆 Performance'!G$5:G$12,6),'🏆 Performance'!G$5:G$12,0)) -> 0 | P29: =LARGE('🏆 Performance'!G$5:G$12,6) -> 26.4
A30: July | B30: =SUMPRODUCT((TEXT('📊 Sales Report'!$A$5:$A$957,"MMMM")=A30)*1) -> 0 | C30: =SUMPRODUCT((TEXT('📊 Sales Report'!$A$5:$A$957,"MMMM")=A30)*'📊 Sales Report'!$I$5:$I$957) -> 0 | D30: =C30-SUMPRODUCT((TEXT('📊 Sales Report'!$A$5:$A$957,"MMMM")=A30)*'📊 Sales Report'!$N$5:$N$957) -> 0 | E30: =SUMPRODUCT((TEXT('📊 Sales Report'!$A$5:$A$957,"MMMM")=A30)*'📊 Sales Report'!$N$5:$N$957) -> 0 | F30: =SUMPRODUCT((TEXT('💸 Expenses'!$A$5:$A$24,"MMMM")=A30)*'💸 Expenses'!$F$5:$F$24) -> 0 | G30: =E30-F30 -> 0 | H30: =IFERROR(G30/C30,0) -> 0 | L30: =INDEX('🏆 Performance'!A$5:A$12,MATCH(LARGE('🏆 Performance'!G$5:G$12,7),'🏆 Performance'!G$5:G$12,0)) -> Roberto Mendoza | M30: =INDEX('🏆 Performance'!B$5:B$12,MATCH(LARGE('🏆 Performance'!G$5:G$12,7),'🏆 Performance'!G$5:G$12,0)) -> 0 | N30: =INDEX('🏆 Performance'!C$5:C$12,MATCH(LARGE('🏆 Performance'!G$5:G$12,7),'🏆 Performance'!G$5:G$12,0)) -> 0 | O30: =INDEX('🏆 Performance'!D$5:D$12,MATCH(LARGE('🏆 Performance'!G$5:G$12,7),'🏆 Performance'!G$5:G$12,0)) -> 0 | P30: =LARGE('🏆 Performance'!G$5:G$12,7) -> 26.4
A31: August | B31: =SUMPRODUCT((TEXT('📊 Sales Report'!$A$5:$A$957,"MMMM")=A31)*1) -> 0 | C31: =SUMPRODUCT((TEXT('📊 Sales Report'!$A$5:$A$957,"MMMM")=A31)*'📊 Sales Report'!$I$5:$I$957) -> 0 | D31: =C31-SUMPRODUCT((TEXT('📊 Sales Report'!$A$5:$A$957,"MMMM")=A31)*'📊 Sales Report'!$N$5:$N$957) -> 0 | E31: =SUMPRODUCT((TEXT('📊 Sales Report'!$A$5:$A$957,"MMMM")=A31)*'📊 Sales Report'!$N$5:$N$957) -> 0 | F31: =SUMPRODUCT((TEXT('💸 Expenses'!$A$5:$A$24,"MMMM")=A31)*'💸 Expenses'!$F$5:$F$24) -> 0 | G31: =E31-F31 -> 0 | H31: =IFERROR(G31/C31,0) -> 0 | L31: =INDEX('🏆 Performance'!A$5:A$12,MATCH(LARGE('🏆 Performance'!G$5:G$12,8),'🏆 Performance'!G$5:G$12,0)) -> Grace Villanueva | M31: =INDEX('🏆 Performance'!B$5:B$12,MATCH(LARGE('🏆 Performance'!G$5:G$12,8),'🏆 Performance'!G$5:G$12,0)) -> 0 | N31: =INDEX('🏆 Performance'!C$5:C$12,MATCH(LARGE('🏆 Performance'!G$5:G$12,8),'🏆 Performance'!G$5:G$12,0)) -> 0 | O31: =INDEX('🏆 Performance'!D$5:D$12,MATCH(LARGE('🏆 Performance'!G$5:G$12,8),'🏆 Performance'!G$5:G$12,0)) -> 0 | P31: =LARGE('🏆 Performance'!G$5:G$12,8) -> 25.2
A32: September | B32: =SUMPRODUCT((TEXT('📊 Sales Report'!$A$5:$A$957,"MMMM")=A32)*1) -> 0 | C32: =SUMPRODUCT((TEXT('📊 Sales Report'!$A$5:$A$957,"MMMM")=A32)*'📊 Sales Report'!$I$5:$I$957) -> 0 | D32: =C32-SUMPRODUCT((TEXT('📊 Sales Report'!$A$5:$A$957,"MMMM")=A32)*'📊 Sales Report'!$N$5:$N$957) -> 0 | E32: =SUMPRODUCT((TEXT('📊 Sales Report'!$A$5:$A$957,"MMMM")=A32)*'📊 Sales Report'!$N$5:$N$957) -> 0 | F32: =SUMPRODUCT((TEXT('💸 Expenses'!$A$5:$A$24,"MMMM")=A32)*'💸 Expenses'!$F$5:$F$24) -> 0 | G32: =E32-F32 -> 0 | H32: =IFERROR(G32/C32,0) -> 0
A33: October | B33: =SUMPRODUCT((TEXT('📊 Sales Report'!$A$5:$A$957,"MMMM")=A33)*1) -> 0 | C33: =SUMPRODUCT((TEXT('📊 Sales Report'!$A$5:$A$957,"MMMM")=A33)*'📊 Sales Report'!$I$5:$I$957) -> 0 | D33: =C33-SUMPRODUCT((TEXT('📊 Sales Report'!$A$5:$A$957,"MMMM")=A33)*'📊 Sales Report'!$N$5:$N$957) -> 0 | E33: =SUMPRODUCT((TEXT('📊 Sales Report'!$A$5:$A$957,"MMMM")=A33)*'📊 Sales Report'!$N$5:$N$957) -> 0 | F33: =SUMPRODUCT((TEXT('💸 Expenses'!$A$5:$A$24,"MMMM")=A33)*'💸 Expenses'!$F$5:$F$24) -> 0 | G33: =E33-F33 -> 0 | H33: =IFERROR(G33/C33,0) -> 0
A34: November | B34: =SUMPRODUCT((TEXT('📊 Sales Report'!$A$5:$A$957,"MMMM")=A34)*1) -> 0 | C34: =SUMPRODUCT((TEXT('📊 Sales Report'!$A$5:$A$957,"MMMM")=A34)*'📊 Sales Report'!$I$5:$I$957) -> 0 | D34: =C34-SUMPRODUCT((TEXT('📊 Sales Report'!$A$5:$A$957,"MMMM")=A34)*'📊 Sales Report'!$N$5:$N$957) -> 0 | E34: =SUMPRODUCT((TEXT('📊 Sales Report'!$A$5:$A$957,"MMMM")=A34)*'📊 Sales Report'!$N$5:$N$957) -> 0 | F34: =SUMPRODUCT((TEXT('💸 Expenses'!$A$5:$A$24,"MMMM")=A34)*'💸 Expenses'!$F$5:$F$24) -> 0 | G34: =E34-F34 -> 0 | H34: =IFERROR(G34/C34,0) -> 0
A35: December | B35: =SUMPRODUCT((TEXT('📊 Sales Report'!$A$5:$A$957,"MMMM")=A35)*1) -> 0 | C35: =SUMPRODUCT((TEXT('📊 Sales Report'!$A$5:$A$957,"MMMM")=A35)*'📊 Sales Report'!$I$5:$I$957) -> 0 | D35: =C35-SUMPRODUCT((TEXT('📊 Sales Report'!$A$5:$A$957,"MMMM")=A35)*'📊 Sales Report'!$N$5:$N$957) -> 0 | E35: =SUMPRODUCT((TEXT('📊 Sales Report'!$A$5:$A$957,"MMMM")=A35)*'📊 Sales Report'!$N$5:$N$957) -> 0 | F35: =SUMPRODUCT((TEXT('💸 Expenses'!$A$5:$A$24,"MMMM")=A35)*'💸 Expenses'!$F$5:$F$24) -> 0 | G35: =E35-F35 -> 0 | H35: =IFERROR(G35/C35,0) -> 0
A37: ⚙ Powered by POS Report Pro • All data auto-linked across sheets • Modify Settings sheet to configure VAT, currency & payroll rates

Sheet 📊 Sales Report
A1: 📊 DAILY SALES REPORT
A4: Date | B4: Invoice # | C4: Product Name | D4: Category | E4: Qty Sold | F4: Unit Price | G4: Discount (%) | H4: Tax (%) | I4: Total Amount | J4: Payment Method | K4: Cashier | L4: Customer Name | M4: Profit/Item | N4: Total Profit
A5: 45658 | B5: INV-01001 | C5: Latte | D5: Beverages | E5: 1 | F5: 4.5 | G5: 0 | H5: 12 | I5: =E5*F5*(1-G5/100)*(1+H5/100) -> 5.04 | J5: GCash | K5: Juan Dela Cruz | L5: Mary Johnson | M5: =F5*(1-G5/100)-2.8 -> 1.7 | N5: =M5*E5 -> 1.7
A6: 45658 | B6: INV-01002 | C6: Latte | D6: Beverages | E6: 5 | F6: 4.5 | G6: 0 | H6: 12 | I6: =E6*F6*(1-G6/100)*(1+H6/100) -> 25.2 | J6: PayMaya | K6: Carlo Bautista | L6: Walk-in | M6: =F6*(1-G6/100)-2.8 -> 1.7 | N6: =M6*E6 -> 8.5
A7: 45658 | B7: INV-01003 | C7: Espresso Coffee | D7: Beverages | E7: 1 | F7: 3.5 | G7: 0 | H7: 12 | I7: =E7*F7*(1-G7/100)*(1+H7/100) -> 3.92 | J7: GCash | K7: Lisa Tan | L7: James Ong | M7: =F7*(1-G7/100)-2.2 -> 1.3 | N7: =M7*E7 -> 1.3
A8: 45658 | B8: INV-01004 | C8: Espresso Coffee | D8: Beverages | E8: 5 | F8: 3.5 | G8: 0 | H8: 12 | I8: =E8*F8*(1-G8/100)*(1+H8/100) -> 19.6 | J8: PayMaya | K8: Carlo Bautista | L8: Robert Brown | M8: =F8*(1-G8/100)-2.2 -> 1.3 | N8: =M8*E8 -> 6.5
A9: 45658 | B9: INV-01005 | C9: Orange Juice | D9: Beverages | E9: 5 | F9: 3 | G9: 0 | H9: 12 | I9: =E9*F9*(1-G9/100)*(1+H9/100) -> 16.8 | J9: Cash | K9: Juan Dela Cruz | L9: Jennifer Cruz | M9: =F9*(1-G9/100)-1.5 -> 1.5 | N9: =M9*E9 -> 7.5
A10: 45658 | B10: INV-01006 | C10: Fried Chicken | D10: Food | E10: 3 | F10: 8.5 | G10: 0 | H10: 12 | I10: =E10*F10*(1-G10/100)*(1+H10/100) -> 28.56 | J10: GCash | K10: Ana Reyes | L10: John Smith | M10: =F10*(1-G10/100)-4.2 -> 4.3 | N10: =M10*E10 -> 12.9
A11: 45658 | B11: INV-01007 | C11: Latte | D11: Beverages | E11: 4 | F11: 4.5 | G11: 0 | H11: 12 | I11: =E11*F11*(1-G11/100)*(1+H11/100) -> 20.16 | J11: Credit Card | K11: Ana Reyes | L11: James Ong | M11: =F11*(1-G11/100)-2.8 -> 1.7 | N11: =M11*E11 -> 6.8
A12: 45658 | B12: INV-01008 | C12: Mineral Water | D12: Beverages | E12: 1 | F12: 1.5 | G12: 5 | H12: 12 | I12: =E12*F12*(1-G12/100)*(1+H12/100) -> 1.596 | J12: PayMaya | K12: Maria Santos | L12: Jennifer Cruz | M12: =F12*(1-G12/100)-0.6 -> 0.825 | N12: =M12*E12 -> 0.825
A13: 45658 | B13: INV-01009 | C13: Latte | D13: Beverages | E13: 5 | F13: 4.5 | G13: 0 | H13: 12 | I13: =E13*F13*(1-G13/100)*(1+H13/100) -> 25.2 | J13: PayMaya | K13: Ana Reyes | L13: James Ong | M13: =F13*(1-G13/100)-2.8 -> 1.7 | N13: =M13*E13 -> 8.5
A14: 45658 | B14: INV-01010 | C14: Chocolate Cake | D14: Bakery | E14: 1 | F14: 5 | G14: 0 | H14: 12 | I14: =E14*F14*(1-G14/100)*(1+H14/100) -> 5.6 | J14: GCash | K14: Ana Reyes | L14: John Smith | M14: =F14*(1-G14/100)-2.5 -> 2.5 | N14: =M14*E14 -> 2.5
A15: 45658 | B15: INV-01011 | C15: Chocolate Cake | D15: Bakery | E15: 1 | F15: 5 | G15: 5 | H15: 12 | I15: =E15*F15*(1-G15/100)*(1+H15/100) -> 5.32 | J15: Credit Card | K15: Carlo Bautista | L15: Michael Garcia | M15: =F15*(1-G15/100)-2.5 -> 2.25 | N15: =M15*E15 -> 2.25
A16: 45658 | B16: INV-01012 | C16: Croissant | D16: Bakery | E16: 3 | F16: 2.5 | G16: 0 | H16: 12 | I16: =E16*F16*(1-G16/100)*(1+H16/100) -> 8.4 | J16: GCash | K16: Ana Reyes | L16: John Smith | M16: =F16*(1-G16/100)-1.1 -> 1.4 | N16: =M16*E16 -> 4.2
A17: 45658 | B17: INV-01013 | C17: Ice Cream | D17: Dessert | E17: 2 | F17: 3.5 | G17: 10 | H17: 12 | I17: =E17*F17*(1-G17/100)*(1+H17/100) -> 7.056 | J17: GCash | K17: Juan Dela Cruz | L17: David Torres | M17: =F17*(1-G17/100)-1.4 -> 1.75 | N17: =M17*E17 -> 3.5
A18: 45658 | B18: INV-01014 | C18: Rice Meal | D18: Food | E18: 3 | F18: 6 | G18: 10 | H18: 12 | I18: =E18*F18*(1-G18/100)*(1+H18/100) -> 18.144 | J18: GCash | K18: Ana Reyes | L18: Walk-in | M18: =F18*(1-G18/100)-2.8 -> 2.6 | N18: =M18*E18 -> 7.8
A19: 45658 | B19: INV-01015 | C19: Chocolate Cake | D19: Bakery | E19: 1 | F19: 5 | G19: 0 | H19: 12 | I19: =E19*F19*(1-G19/100)*(1+H19/100) -> 5.6 | J19: Debit Card | K19: Ana Reyes | L19: John Smith | M19: =F19*(1-G19/100)-2.5 -> 2.5 | N19: =M19*E19 -> 2.5
A20: 45659 | B20: INV-01016 | C20: Ice Cream | D20: Dessert | E20: 3 | F20: 3.5 | G20: 0 | H20: 12 | I20: =E20*F20*(1-G20/100)*(1+H20/100) -> 11.76 | J20: Debit Card | K20: Carlo Bautista | L20: David Torres | M20: =F20*(1-G20/100)-1.4 -> 2.1 | N20: =M20*E20 -> 6.3
A21: 45659 | B21: INV-01017 | C21: Croissant | D21: Bakery | E21: 3 | F21: 2.5 | G21: 0 | H21: 12 | I21: =E21*F21*(1-G21/100)*(1+H21/100) -> 8.4 | J21: GCash | K21: Lisa Tan | L21: Patricia Ramos | M21: =F21*(1-G21/100)-1.1 -> 1.4 | N21: =M21*E21 -> 4.2
A22: 45659 | B22: INV-01018 | C22: Mineral Water | D22: Beverages | E22: 5 | F22: 1.5 | G22: 5 | H22: 12 | I22: =E22*F22*(1-G22/100)*(1+H22/100) -> 7.98 | J22: PayMaya | K22: Carlo Bautista | L22: Michael Garcia | M22: =F22*(1-G22/100)-0.6 -> 0.825 | N22: =M22*E22 -> 4.125
A23: 45659 | B23: INV-01019 | C23: Chocolate Cake | D23: Bakery | E23: 2 | F23: 5 | G23: 10 | H23: 12 | I23: =E23*F23*(1-G23/100)*(1+H23/100) -> 10.08 | J23: Debit Card | K23: Maria Santos | L23: Walk-in | M23: =F23*(1-G23/100)-2.5 -> 2 | N23: =M23*E23 -> 4
A24: 45659 | B24: INV-01020 | C24: Latte | D24: Beverages | E24: 2 | F24: 4.5 | G24: 0 | H24: 12 | I24: =E24*F24*(1-G24/100)*(1+H24/100) -> 10.08 | J24: Debit Card | K24: Lisa Tan | L24: John Smith | M24: =F24*(1-G24/100)-2.8 -> 1.7 | N24: =M24*E24 -> 3.4
A25: 45659 | B25: INV-01021 | C25: Rice Meal | D25: Food | E25: 4 | F25: 6 | G25: 10 | H25: 12 | I25: =E25*F25*(1-G25/100)*(1+H25/100) -> 24.192 | J25: Debit Card | K25: Lisa Tan | L25: Anna Lee | M25: =F25*(1-G25/100)-2.8 -> 2.6 | N25: =M25*E25 -> 10.4
A26: 45659 | B26: INV-01022 | C26: Sandwich | D26: Food | E26: 1 | F26: 4 | G26: 0 | H26: 12 | I26: =E26*F26*(1-G26/100)*(1+H26/100) -> 4.48 | J26: PayMaya | K26: Ana Reyes | L26: Michael Garcia | M26: =F26*(1-G26/100)-1.8 -> 2.2 | N26: =M26*E26 -> 2.2
A27: 45659 | B27: INV-01023 | C27: Latte | D27: Beverages | E27: 3 | F27: 4.5 | G27: 5 | H27: 12 | I27: =E27*F27*(1-G27/100)*(1+H27/100) -> 14.364 | J27: GCash | K27: Carlo Bautista | L27: Walk-in | M27: =F27*(1-G27/100)-2.8 -> 1.475 | N27: =M27*E27 -> 4.425
A28: 45660 | B28: INV-01024 | C28: Sandwich | D28: Food | E28: 2 | F28: 4 | G28: 10 | H28: 12 | I28: =E28*F28*(1-G28/100)*(1+H28/100) -> 8.064 | J28: Cash | K28: Ana Reyes | L28: Patricia Ramos | M28: =F28*(1-G28/100)-1.8 -> 1.8 | N28: =M28*E28 -> 3.6
A29: 45660 | B29: INV-01025 | C29: Ice Cream | D29: Dessert | E29: 2 | F29: 3.5 | G29: 0 | H29: 12 | I29: =E29*F29*(1-G29/100)*(1+H29/100) -> 7.84 | J29: Credit Card | K29: Juan Dela Cruz | L29: Patricia Ramos | M29: =F29*(1-G29/100)-1.4 -> 2.1 | N29: =M29*E29 -> 4.2
A30: 45660 | B30: INV-01026 | C30: Sandwich | D30: Food | E30: 1 | F30: 4 | G30: 10 | H30: 12 | I30: =E30*F30*(1-G30/100)*(1+H30/100) -> 4.032 | J30: Credit Card | K30: Carlo Bautista | L30: Walk-in | M30: =F30*(1-G30/100)-1.8 -> 1.8 | N30: =M30*E30 -> 1.8
A31: 45660 | B31: INV-01027 | C31: Latte | D31: Beverages | E31: 3 | F31: 4.5 | G31: 0 | H31: 12 | I31: =E31*F31*(1-G31/100)*(1+H31/100) -> 15.12 | J31: GCash | K31: Maria Santos | L31: Robert Brown | M31: =F31*(1-G31/100)-2.8 -> 1.7 | N31: =M31*E31 -> 5.1
A32: 45660 | B32: INV-01028 | C32: Ice Cream | D32: Dessert | E32: 1 | F32: 3.5 | G32: 0 | H32: 12 | I32: =E32*F32*(1-G32/100)*(1+H32/100) -> 3.92 | J32: Debit Card | K32: Maria Santos | L32: Patricia Ramos | M32: =F32*(1-G32/100)-1.4 -> 2.1 | N32: =M32*E32 -> 2.1
A33: 45660 | B33: INV-01029 | C33: Croissant | D33: Bakery | E33: 2 | F33: 2.5 | G33: 5 | H33: 12 | I33: =E33*F33*(1-G33/100)*(1+H33/100) -> 5.32 | J33: PayMaya | K33: Juan Dela Cruz | L33: Anna Lee | M33: =F33*(1-G33/100)-1.1 -> 1.275 | N33: =M33*E33 -> 2.55
A34: 45660 | B34: INV-01030 | C34: Sandwich | D34: Food | E34: 5 | F34: 4 | G34: 5 | H34: 12 | I34: =E34*F34*(1-G34/100)*(1+H34/100) -> 21.28 | J34: GCash | K34: Lisa Tan | L34: Robert Brown | M34: =F34*(1-G34/100)-1.8 -> 2 | N34: =M34*E34 -> 10
A35: 45660 | B35: INV-01031 | C35: Mineral Water | D35: Beverages | E35: 4 | F35: 1.5 | G35: 0 | H35: 12 | I35: =E35*F35*(1-G35/100)*(1+H35/100) -> 6.72 | J35: Debit Card | K35: Lisa Tan | L35: David Torres | M35: =F35*(1-G35/100)-0.6 -> 0.9 | N35: =M35*E35 -> 3.6
A36: 45660 | B36: INV-01032 | C36: Latte | D36: Beverages | E36: 2 | F36: 4.5 | G36: 0 | H36: 12 | I36: =E36*F36*(1-G36/100)*(1+H36/100) -> 10.08 | J36: Cash | K36: Ana Reyes | L36: Walk-in | M36: =F36*(1-G36/100)-2.8 -> 1.7 | N36: =M36*E36 -> 3.4
A37: 45661 | B37: INV-01033 | C37: Sandwich | D37: Food | E37: 2 | F37: 4 | G37: 10 | H37: 12 | I37: =E37*F37*(1-G37/100)*(1+H37/100) -> 8.064 | J37: GCash | K37: Maria Santos | L37: John Smith | M37: =F37*(1-G37/100)-1.8 -> 1.8 | N37: =M37*E37 -> 3.6
A38: 45661 | B38: INV-01034 | C38: Espresso Coffee | D38: Beverages | E38: 2 | F38: 3.5 | G38: 0 | H38: 12 | I38: =E38*F38*(1-G38/100)*(1+H38/100) -> 7.84 | J38: Cash | K38: Ana Reyes | L38: John Smith | M38: =F38*(1-G38/100)-2.2 -> 1.3 | N38: =M38*E38 -> 2.6
A39: 45661 | B39: INV-01035 | C39: Sandwich | D39: Food | E39: 2 | F39: 4 | G39: 0 | H39: 12 | I39: =E39*F39*(1-G39/100)*(1+H39/100) -> 8.96 | J39: Debit Card | K39: Juan Dela Cruz | L39: Patricia Ramos | M39: =F39*(1-G39/100)-1.8 -> 2.2 | N39: =M39*E39 -> 4.4
A40: 45661 | B40: INV-01036 | C40: Croissant | D40: Bakery | E40: 5 | F40: 2.5 | G40: 10 | H40: 12 | I40: =E40*F40*(1-G40/100)*(1+H40/100) -> 12.6 | J40: Debit Card | K40: Juan Dela Cruz | L40: David Torres | M40: =F40*(1-G40/100)-1.1 -> 1.15 | N40: =M40*E40 -> 5.75
A41: 45661 | B41: INV-01037 | C41: Rice Meal | D41: Food | E41: 2 | F41: 6 | G41: 0 | H41: 12 | I41: =E41*F41*(1-G41/100)*(1+H41/100) -> 13.44 | J41: Cash | K41: Carlo Bautista | L41: Michael Garcia | M41: =F41*(1-G41/100)-2.8 -> 3.2 | N41: =M41*E41 -> 6.4
A42: 45661 | B42: INV-01038 | C42: Rice Meal | D42: Food | E42: 4 | F42: 6 | G42: 5 | H42: 12 | I42: =E42*F42*(1-G42/100)*(1+H42/100) -> 25.536 | J42: Cash | K42: Maria Santos | L42: Walk-in | M42: =F42*(1-G42/100)-2.8 -> 2.9 | N42: =M42*E42 -> 11.6
...

Sheet 📦 Inventory
A1: 📦 PRODUCT INVENTORY MANAGEMENT
A4: Product ID | B4: Barcode | C4: Product Name | D4: Category | E4: Supplier | F4: Cost Price | G4: Selling Price | H4: Current Stock | I4: Min Stock Level | J4: Stock Status | K4: Inventory Value | L4: Expiry Date
A5: PROD-001 | B5: 8901234567890 | C5: Espresso Coffee (kg) | D5: Beverages | E5: CoffeeSup Co | F5: 350 | G5: 500 | H5: 45 | I5: 10 | J5: =IF(H5=0,"OUT OF STOCK",IF(H5<=I5,"LOW STOCK","In Stock")) -> In Stock | K5: =H5*G5 -> 22500 | L5: 46174
A6: PROD-002 | B6: 8901234567891 | C6: Latte Mix (pack) | D6: Beverages | E6: CoffeeSup Co | F6: 280 | G6: 420 | H6: 30 | I6: 10 | J6: =IF(H6=0,"OUT OF STOCK",IF(H6<=I6,"LOW STOCK","In Stock")) -> In Stock | K6: =H6*G6 -> 12600 | L6: 46157
A7: PROD-003 | B7: 8901234567892 | C7: Croissant (pcs) | D7: Bakery | E7: BakeryWorld | F7: 22 | G7: 45 | H7: 8 | I7: 15 | J7: =IF(H7=0,"OUT OF STOCK",IF(H7<=I7,"LOW STOCK","In Stock")) -> LOW STOCK | K7: =H7*G7 -> 360 | L7: 45767
A8: PROD-004 | B8: 8901234567893 | C8: Chocolate Cake (slice) | D8: Bakery | E8: BakeryWorld | F8: 75 | G8: 150 | H8: 20 | I8: 10 | J8: =IF(H8=0,"OUT OF STOCK",IF(H8<=I8,"LOW STOCK","In Stock")) -> In Stock | K8: =H8*G8 -> 3000 | L8: 45765
A9: PROD-005 | B9: 8901234567894 | C9: Mineral Water (500ml) | D9: Beverages | E9: AquaSupplies | F9: 12 | G9: 28 | H9: 120 | I9: 30 | J9: =IF(H9=0,"OUT OF STOCK",IF(H9<=I9,"LOW STOCK","In Stock")) -> In Stock | K9: =H9*G9 -> 3360 | L9: 46387
A10: PROD-006 | B10: 8901234567895 | C10: Fried Chicken (piece) | D10: Food | E10: MeatHouse PH | F10: 65 | G10: 180 | H10: 40 | I10: 20 | J10: =IF(H10=0,"OUT OF STOCK",IF(H10<=I10,"LOW STOCK","In Stock")) -> In Stock | K10: =H10*G10 -> 7200 | L10: 45769
A11: PROD-007 | B11: 8901234567896 | C11: Rice (kg) | D11: Grains | E11: GrainsMart | F11: 42 | G11: 80 | H11: 200 | I11: 50 | J11: =IF(H11=0,"OUT OF STOCK",IF(H11<=I11,"LOW STOCK","In Stock")) -> In Stock | K11: =H11*G11 -> 16000 | L11: 46388
A12: PROD-008 | B12: 8901234567897 | C12: Orange Juice (bottle) | D12: Beverages | E12: FreshDrinks | F12: 40 | G12: 85 | H12: 55 | I12: 15 | J12: =IF(H12=0,"OUT OF STOCK",IF(H12<=I12,"LOW STOCK","In Stock")) -> In Stock | K12: =H12*G12 -> 4675 | L12: 45838
A13: PROD-009 | B13: 8901234567898 | C13: Sandwich Bread (loaf) | D13: Bakery | E13: BakeryWorld | F13: 45 | G13: 90 | H13: 12 | I13: 20 | J13: =IF(H13=0,"OUT OF STOCK",IF(H13<=I13,"LOW STOCK","In Stock")) -> LOW STOCK | K13: =H13*G13 -> 1080 | L13: 45772
A14: PROD-010 | B14: 8901234567899 | C14: Ice Cream (cup) | D14: Dessert | E14: CoolTreats | F14: 35 | G14: 70 | H14: 25 | I14: 10 | J14: =IF(H14=0,"OUT OF STOCK",IF(H14<=I14,"LOW STOCK","In Stock")) -> In Stock | K14: =H14*G14 -> 1750 | L14: 45931
A15: PROD-011 | B15: 8901234567900 | C15: Sugar (kg) | D15: Supplies | E15: GrainsMart | F15: 30 | G15: 58 | H15: 80 | I15: 30 | J15: =IF(H15=0,"OUT OF STOCK",IF(H15<=I15,"LOW STOCK","In Stock")) -> In Stock | K15: =H15*G15 -> 4640 | L15: 46539
A16: PROD-012 | B16: 8901234567901 | C16: Cooking Oil (liter) | D16: Supplies | E16: OilPro | F16: 75 | G16: 140 | H16: 35 | I16: 15 | J16: =IF(H16=0,"OUT OF STOCK",IF(H16<=I16,"LOW STOCK","In Stock")) -> In Stock | K16: =H16*G16 -> 4900 | L16: 46235
... A19: PROD-015 | B19: 8901234567904 | C19: Bottled Soda (330ml) | D19: Beverages | E19: SodaDistrib | F19: 18 | G19: 40 | H19: 90 | I19: 30 | J19: =IF(H19=0,"OUT OF STOCK",IF(H19<=I19,"LOW STOCK","In Stock")) -> In Stock | K19: =H19*G19 -> 3600 | L19: 46082
A21: TOTAL INVENTORY VALUE | K21: =SUM(K5:K19) -> 89765

Sheet 💸 Expenses
A1: 💸 EXPENSE TRACKING SHEET
A4: Date | B4: Expense Category | C4: Description | D4: Supplier/Vendor | E4: Payment Method | F4: Amount | G4: Approved By | I4: MONTHLY EXPENSE SUMMARY
A5: 45662 | B5: Rent | C5: Monthly Store Rent | D5: LandlordPH | E5: Cash | F5: 25000 | G5: Owner | I5: Month | J5: Category | K5: Total
A6: 45664 | B6: Utilities | C6: Electricity Bill | D6: Meralco | E6: Bank Transfer | F6: 4800 | G6: Manager | I6: January | J6: Utilities | K6: =SUMPRODUCT((TEXT($A$5:$A$24,"MMMM")=I6)*($B$5:$B$24=J6)*($F$5:$F$24)) -> 5450
A7: 45667 | B7: Internet | C7: Fiber Internet | D7: PLDT | E7: Auto-Debit | F7: 1999 | G7: Manager | I7: January | J7: Rent | K7: =SUMPRODUCT((TEXT($A$5:$A$24,"MMMM")=I7)*($B$5:$B$24=J7)*($F$5:$F$24)) -> 25000
A8: 45669 | B8: Supplies | C8: Cleaning Supplies | D8: SM Supermarket | E8: Cash | F8: 850 | G8: Staff | I8: January | J8: Internet | K8: =SUMPRODUCT((TEXT($A$5:$A$24,"MMMM")=I8)*($B$5:$B$24=J8)*($F$5:$F$24)) -> 1999
A9: 45672 | B9: Marketing | C9: Social Media Ads | D9: Facebook | E9: Credit Card | F9: 3500 | G9: Owner | I9: January | J9: Supplies | K9: =SUMPRODUCT((TEXT($A$5:$A$24,"MMMM")=I9)*($B$5:$B$24=J9)*($F$5:$F$24)) -> 850
A10: 45675 | B10: Repairs | C10: HVAC Service | D10: CoolAir Tech | E10: Cash | F10: 2800 | G10: Manager | I10: January | J10: Repairs | K10: =SUMPRODUCT((TEXT($A$5:$A$24,"MMMM")=I10)*($B$5:$B$24=J10)*($F$5:$F$24)) -> 2800
A11: 45677 | B11: Transportation | C11: Delivery Gas | D11: Petron | E11: Cash | F11: 1200 | G11: Staff | I11: January | J11: Marketing | K11: =SUMPRODUCT((TEXT($A$5:$A$24,"MMMM")=I11)*($B$5:$B$24=J11)*($F$5:$F$24)) -> 3500
A12: 45682 | B12: Utilities | C12: Water Bill | D12: Maynilad | E12: Bank Transfer | F12: 650 | G12: Manager | I12: January | J12: Transportation | K12: =SUMPRODUCT((TEXT($A$5:$A$24,"MMMM")=I12)*($B$5:$B$24=J12)*($F$5:$F$24)) -> 1200
A13: 45693 | B13: Rent | C13: Monthly Store Rent | D13: LandlordPH | E13: Cash | F13: 25000 | G13: Owner | I13: January | J13: Payroll | K13: =SUMPRODUCT((TEXT($A$5:$A$24,"MMMM")=I13)*($B$5:$B$24=J13)*($F$5:$F$24)) -> 0
A14: 45696 | B14: Utilities | C14: Electricity Bill | D14: Meralco | E14: Bank Transfer | F14: 5100 | G14: Manager | I14: January | J14: Miscellaneous | K14: =SUMPRODUCT((TEXT($A$5:$A$24,"MMMM")=I14)*($B$5:$B$24=J14)*($F$5:$F$24)) -> 0
A15: 45698 | B15: Internet | C15: Fiber Internet | D15: PLDT | E15: Auto-Debit | F15: 1999 | G15: Manager | I15: February | J15: Utilities | K15: =SUMPRODUCT((TEXT($A$5:$A$24,"MMMM")=I15)*($B$5:$B$24=J15)*($F$5:$F$24)) -> 5100
A16: 45702 | B16: Marketing | C16: Valentine Promo Print | D16: PrintMaster | E16: Cash | F16: 2000 | G16: Owner | I16: February | J16: Rent | K16: =SUMPRODUCT((TEXT($A$5:$A$24,"MMMM")=I16)*($B$5:$B$24=J16)*($F$5:$F$24)) -> 25000
A17: 45706 | B17: Supplies | C17: Paper Bags & Cups | D17: PackagePro | E17: Cash | F17: 1500 | G17: Staff | I17: February | J17: Internet | K17: =SUMPRODUCT((TEXT($A$5:$A$24,"MMMM")=I17)*($B$5:$B$24=J17)*($F$5:$F$24)) -> 1999
... A24: 45741 | B24: Transportation | C24: Supplier Delivery | D24: Grab Express | E24: GCash | F24: 800 | G24: Staff | I24: March | J24: Utilities | K24: =SUMPRODUCT((TEXT($A$5:$A$24,"MMMM")=I24)*($B$5:$B$24=J24)*($F$5:$F$24)) -> 4600
I25: March | J25: Rent | K25: =SUMPRODUCT((TEXT($A$5:$A$24,"MMMM")=I25)*($B$5:$B$24=J25)*($F$5:$F$24)) -> 25000
A26: TOTAL EXPENSES | F26: =SUM(F5:F24) -> 113497 | I26: March | J26: Internet | K26: =SUMPRODUCT((TEXT($A$5:$A$24,"MMMM")=I26)*($B$5:$B$24=J26)*($F$5:$F$24)) -> 1999
I27: March | J27: Supplies | K27: =SUMPRODUCT((TEXT($A$5:$A$24,"MMMM")=I27)*($B$5:$B$24=J27)*($F$5:$F$24)) -> 750
I28: March | J28: Repairs | K28: =SUMPRODUCT((TEXT($A$5:$A$24,"MMMM")=I28)*($B$5:$B$24=J28)*($F$5:$F$24)) -> 3500
I29: March | J29: Marketing | K29: =SUMPRODUCT((TEXT($A$5:$A$24,"MMMM")=I29)*($B$5:$B$24=J29)*($F$5:$F$24)) -> 0
I30: Expense Distribution | J30: Transportation | K30: =SUMPRODUCT((TEXT($A$5:$A$24,"MMMM")=I30)*($B$5:$B$24=J30)*($F$5:$F$24)) -> 0
I31: Utilities | J31: =SUMIF($B$5:$B$24,I31,$F$5:$F$24) -> 15150 | K31: =SUMPRODUCT((TEXT($A$5:$A$24,"MMMM")=I31)*($B$5:$B$24=J31)*($F$5:$F$24)) -> 0
I32: Rent | J32: =SUMIF($B$5:$B$24,I32,$F$5:$F$24) -> 75000 | K32: =SUMPRODUCT((TEXT($A$5:$A$24,"MMMM")=I32)*($B$5:$B$24=J32)*($F$5:$F$24)) -> 0
I33: Internet | J33: =SUMIF($B$5:$B$24,I33,$F$5:$F$24) -> 5997
I34: Supplies | J34: =SUMIF($B$5:$B$24,I34,$F$5:$F$24) -> 3100
I35: Repairs | J35: =SUMIF($B$5:$B$24,I35,$F$5:$F$24) -> 6300
I36: Marketing | J36: =SUMIF($B$5:$B$24,I36,$F$5:$F$24) -> 5500
I37: Transportation | J37: =SUMIF($B$5:$B$24,I37,$F$5:$F$24) -> 2000
I38: Payroll | J38: =SUMIF($B$5:$B$24,I38,$F$5:$F$24) -> 0
I39: Miscellaneous | J39: =SUMIF($B$5:$B$24,I39,$F$5:$F$24) -> 450

Sheet 👥 Payroll
A1: 👥 PAYROLL & SALARY CALCULATION
A4: Emp ID | B4: Employee Name | C4: Position | D4: Daily Rate | E4: Attendance Days | F4: Hours Worked | G4: OT Hours | H4: OT Pay | I4: Gross Salary | J4: SSS | K4: PhilHealth | L4: Pag-IBIG | M4: Late Penalty | N4: Net Salary
A5: EMP-001 | B5: Maria Santos | C5: Cashier | D5: 650 | E5: 22 | F5: 176 | G5: 4 | H5: =ROUND((D5/8)*1.25*G5,2) -> 406.25 | I5: =D5*E5+H5 -> 14706.25 | J5: 500 | K5: 250 | L5: 100 | M5: 0 | N5: =I5-J5-K5-L5-M5 -> 13856.25
A6: EMP-002 | B6: Juan Dela Cruz | C6: Cashier | D6: 650 | E6: 24 | F6: 192 | G6: 8 | H6: =ROUND((D6/8)*1.25*G6,2) -> 812.5 | I6: =D6*E6+H6 -> 16412.5 | J6: 500 | K6: 250 | L6: 100 | M6: 50 | N6: =I6-J6-K6-L6-M6 -> 15512.5
A7: EMP-003 | B7: Ana Reyes | C7: Supervisor | D7: 900 | E7: 23 | F7: 184 | G7: 2 | H7: =ROUND((D7/8)*1.25*G7,2) -> 281.25 | I7: =D7*E7+H7 -> 20981.25 | J7: 500 | K7: 250 | L7: 100 | M7: 0 | N7: =I7-J7-K7-L7-M7 -> 20131.25
A8: EMP-004 | B8: Carlo Bautista | C8: Cashier | D8: 650 | E8: 21 | F8: 168 | G8: 0 | H8: =ROUND((D8/8)*1.25*G8,2) -> 0 | I8: =D8*E8+H8 -> 13650 | J8: 500 | K8: 250 | L8: 100 | M8: 200 | N8: =I8-J8-K8-L8-M8 -> 12600
A9: EMP-005 | B9: Lisa Tan | C9: Barista | D9: 700 | E9: 24 | F9: 192 | G9: 6 | H9: =ROUND((D9/8)*1.25*G9,2) -> 656.25 | I9: =D9*E9+H9 -> 17456.25 | J9: 500 | K9: 250 | L9: 100 | M9: 0 | N9: =I9-J9-K9-L9-M9 -> 16606.25
A10: EMP-006 | B10: Roberto Mendoza | C10: Cook | D10: 750 | E10: 22 | F10: 176 | G10: 5 | H10: =ROUND((D10/8)*1.25*G10,2) -> 585.94 | I10: =D10*E10+H10 -> 17085.94 | J10: 500 | K10: 250 | L10: 100 | M10: 100 | N10: =I10-J10-K10-L10-M10 -> 16135.94
A11: EMP-007 | B11: Grace Villanueva | C11: Waitress | D11: 600 | E11: 20 | F11: 160 | G11: 0 | H11: =ROUND((D11/8)*1.25*G11,2) -> 0 | I11: =D11*E11+H11 -> 12000 | J11: 500 | K11: 250 | L11: 100 | M11: 150 | N11: =I11-J11-K11-L11-M11 -> 11000
A12: EMP-008 | B12: Mark Aquino | C12: Cashier | D12: 650 | E12: 23 | F12: 184 | G12: 3 | H12: =ROUND((D12/8)*1.25*G12,2) -> 304.69 | I12: =D12*E12+H12 -> 15254.69 | J12: 500 | K12: 250 | L12: 100 | M12: 50 | N12: =I12-J12-K12-L12-M12 -> 14354.69
A14: TOTAL PAYROLL | I14: =SUM(I5:I12) -> 127546.88 | N14: =SUM(N5:N12) -> 120196.88

Sheet 🏆 Performance
A1: 🏆 EMPLOYEE PERFORMANCE TRACKER
A4: Employee Name | B4: Total Sales | C4: Transactions | D4: Avg Sale | E4: Attendance % | F4: Customer Rating | G4: Performance Score | H4: Rank
A5: Maria Santos | B5: =SUMIF('📊 Sales Report'!K$5:K$957,A5,'📊 Sales Report'!I$5:I$957) -> 2647.876 | C5: =COUNTIF('📊 Sales Report'!K$5:K$957,A5) -> 183 | D5: =IFERROR(B5/C5,0) -> 14.469268 | E5: 91.1 | F5: 4.2 | G5: =ROUND((B5/MAX($B$5:$B$12)*40)+(C5/MAX($C$5:$C$12)*30)+(F5/5*30),1) -> 90.9 | H5: =RANK(G5,$G$5:$G$12,0) -> 5
A6: Juan Dela Cruz | B6: =SUMIF('📊 Sales Report'!K$5:K$957,A6,'📊 Sales Report'!I$5:I$957) -> 2721.768 | C6: =COUNTIF('📊 Sales Report'!K$5:K$957,A6) -> 205 | D6: =IFERROR(B6/C6,0) -> 13.276917 | E6: 87.7 | F6: 4.2 | G6: =ROUND((B6/MAX($B$5:$B$13)*40)+(C6/MAX($C$5:$C$13)*30)+(F6/5*30),1) -> 95.2 | H6: =RANK(G6,$G$5:$G$12,0) -> 1
A7: Ana Reyes | B7: =SUMIF('📊 Sales Report'!K$5:K$957,A7,'📊 Sales Report'!I$5:I$957) -> 2649.668 | C7: =COUNTIF('📊 Sales Report'!K$5:K$957,A7) -> 191 | D7: =IFERROR(B7/C7,0) -> 13.872607 | E7: 96.4 | F7: 4.3 | G7: =ROUND((B7/MAX($B$5:$B$14)*40)+(C7/MAX($C$5:$C$14)*30)+(F7/5*30),1) -> 92.7 | H7: =RANK(G7,$G$5:$G$12,0) -> 3
A8: Carlo Bautista | B8: =SUMIF('📊 Sales Report'!K$5:K$957,A8,'📊 Sales Report'!I$5:I$957) -> 2451.792 | C8: =COUNTIF('📊 Sales Report'!K$5:K$957,A8) -> 186 | D8: =IFERROR(B8/C8,0) -> 13.181677 | E8: 90.7 | F8: 4.7 | G8: =ROUND((B8/MAX($B$5:$B$15)*40)+(C8/MAX($C$5:$C$15)*30)+(F8/5*30),1) -> 91.5 | H8: =RANK(G8,$G$5:$G$12,0) -> 4
A9: Lisa Tan | B9: =SUMIF('📊 Sales Report'!K$5:K$957,A9,'📊 Sales Report'!I$5:I$957) -> 2501.632 | C9: =COUNTIF('📊 Sales Report'!K$5:K$957,A9) -> 188 | D9: =IFERROR(B9/C9,0) -> 13.306553 | E9: 93.1 | F9: 4.9 | G9: =ROUND((B9/MAX($B$5:$B$16)*40)+(C9/MAX($C$5:$C$16)*30)+(F9/5*30),1) -> 93.7 | H9: =RANK(G9,$G$5:$G$12,0) -> 2
A10: Roberto Mendoza | B10: =SUMIF('📊 Sales Report'!K$5:K$957,A10,'📊 Sales Report'!I$5:I$957) -> 0 | C10: =COUNTIF('📊 Sales Report'!K$5:K$957,A10) -> 0 | D10: =IFERROR(B10/C10,0) -> 0 | E10: 92.3 | F10: 4.4 | G10: =ROUND((B10/MAX($B$5:$B$17)*40)+(C10/MAX($C$5:$C$17)*30)+(F10/5*30),1) -> 26.4 | H10: =RANK(G10,$G$5:$G$12,0) -> 6
A11: Grace Villanueva | B11: =SUMIF('📊 Sales Report'!K$5:K$957,A11,'📊 Sales Report'!I$5:I$957) -> 0 | C11: =COUNTIF('📊 Sales Report'!K$5:K$957,A11) -> 0 | D11: =IFERROR(B11/C11,0) -> 0 | E11: 94.2 | F11: 4.2 | G11: =ROUND((B11/MAX($B$5:$B$18)*40)+(C11/MAX($C$5:$C$18)*30)+(F11/5*30),1) -> 25.2 | H11: =RANK(G11,$G$5:$G$12,0) -> 8
A12: Mark Aquino | B12: =SUMIF('📊 Sales Report'!K$5:K$957,A12,'📊 Sales Report'!I$5:I$957) -> 0 | C12: =COUNTIF('📊 Sales Report'!K$5:K$957,A12) -> 0 | D12: =IFERROR(B12/C12,0) -> 0 | E12: 98.5 | F12: 4.4 | G12: =ROUND((B12/MAX($B$5:$B$19)*40)+(C12/MAX($C$5:$C$19)*30)+(F12/5*30),1) -> 26.4 | H12: =RANK(G12,$G$5:$G$12,0) -> 6

Sheet 🚚 Suppliers
A1: 🚚 SUPPLIER & PURCHASE RECORDS
A4: Purchase Date | B4: Supplier Name | C4: Product Purchased | D4: Quantity | E4: Unit Cost | F4: Total Amount | G4: Delivery Status | H4: Payment Status
A5: 45660 | B5: CoffeeSup Co | C5: Espresso Coffee (kg) | D5: 50 | E5: 300 | F5: =D5*E5 -> 15000 | G5: Delivered | H5: Paid
A6: 45662 | B6: BakeryWorld | C6: Croissant Dough (kg) | D6: 30 | E6: 200 | F6: =D6*E6 -> 6000 | G6: Delivered | H6: Paid
A7: 45665 | B7: MeatHouse PH | C7: Whole Chicken (kg) | D7: 40 | E7: 320 | F7: =D7*E7 -> 12800 | G7: Delivered | H7: Paid
A8: 45667 | B8: AquaSupplies | C8: Mineral Water 500ml (case) | D8: 100 | E8: 10 | F8: =D8*E8 -> 1000 | G8: Delivered | H8: Paid
A9: 45672 | B9: GrainsMart | C9: Rice (50kg sack) | D9: 10 | E9: 2100 | F9: =D9*E9 -> 21000 | G9: Delivered | H9: Pending
A10: 45675 | B10: OilPro | C10: Cooking Oil 1L | D10: 24 | E10: 70 | F10: =D10*E10 -> 1680 | G10: Delivered | H10: Paid
A11: 45679 | B11: PackagePro | C11: Disposable Cups 100pcs | D11: 20 | E11: 115 | F11: =D11*E11 -> 2300 | G11: In Transit | H11: Pending
A12: 45691 | B12: CoffeeSup Co | C12: Latte Mix (pack) | D12: 40 | E12: 260 | F12: =D12*E12 -> 10400 | G12: Delivered | H12: Paid
A13: 45695 | B13: BakeryWorld | C13: Sandwich Bread (loaf) | D13: 50 | E13: 40 | F13: =D13*E13 -> 2000 | G13: Delivered | H13: Paid
A14: 45698 | B14: FreshDrinks | C14: Orange Juice (case) | D14: 30 | E14: 36 | F14: =D14*E14 -> 1080 | G14: Delivered | H14: Paid
A15: 45702 | B15: CoolTreats | C15: Ice Cream Cups (box) | D15: 20 | E15: 32 | F15: =D15*E15 -> 640 | G15: Delivered | H15: Pending
A16: 45706 | B16: SodaDistrib | C16: Bottled Soda 330ml (case) | D16: 60 | E16: 16 | F16: =D16*E16 -> 960 | G16: In Transit | H16: Pending
... A19: 45724 | B19: PackagePro | C19: Napkins (pack) | D19: 80 | E19: 22 | F19: =D19*E19 -> 1760 | G19: Ordered | H19: Pending
A21: TOTAL PURCHASES | F21: =SUM(F5:F19) -> 84220
A22: OUTSTANDING (PENDING) | F22: =SUMIF($H$5:$H$19,"Pending",$F$5:$F$19) -> 26660

Sheet 💰 Cash Flow
A1: 💰 DAILY CASH FLOW REGISTER
A4: Date | B4: Opening Balance | C4: Cash In (Sales) | D4: Cash Out (Expenses) | E4: Bank Deposit | F4: Withdrawal | G4: Petty Cash | H4: Closing Balance
A5: 45658 | B5: 50000 | C5: 10960 | D5: 2607 | E5: 2457 | F5: 0 | G5: 509 | H5: =B5+C5-D5-E5+F5-G5 -> 55387
A6: 45659 | B6: =H5 -> 55387 | C6: 10610 | D6: 2505 | E6: 4946 | F6: 0 | G6: 290 | H6: =B6+C6-D6-E6+F6-G6 -> 58256
A7: 45660 | B7: =H6 -> 58256 | C7: 19522 | D7: 4866 | E7: 8856 | F7: 0 | G7: 594 | H7: =B7+C7-D7-E7+F7-G7 -> 63462
A8: 45661 | B8: =H7 -> 63462 | C8: 20710 | D8: 5124 | E8: 6647 | F8: 0 | G8: 525 | H8: =B8+C8-D8-E8+F8-G8 -> 71876
A9: 45662 | B9: =H8 -> 71876 | C9: 22053 | D9: 5376 | E9: 12664 | F9: 0 | G9: 241 | H9: =B9+C9-D9-E9+F9-G9 -> 75648
A10: 45663 | B10: =H9 -> 75648 | C10: 16429 | D10: 1336 | E10: 3778 | F10: 0 | G10: 725 | H10: =B10+C10-D10-E10+F10-G10 -> 86238
A11: 45664 | B11: =H10 -> 86238 | C11: 8476 | D11: 5672 | E11: 7610 | F11: 0 | G11: 429 | H11: =B11+C11-D11-E11+F11-G11 -> 81003
A12: 45665 | B12: =H11 -> 81003 | C12: 9719 | D12: 4101 | E12: 3796 | F12: 0 | G12: 290 | H12: =B12+C12-D12-E12+F12-G12 -> 82535
A13: 45666 | B13: =H12 -> 82535 | C13: 24448 | D13: 4507 | E13: 3196 | F13: 0 | G13: 432 | H13: =B13+C13-D13-E13+F13-G13 -> 98848
A14: 45667 | B14: =H13 -> 98848 | C14: 14725 | D14: 4361 | E14: 2786 | F14: 0 | G14: 512 | H14: =B14+C14-D14-E14+F14-G14 -> 105914
A15: 45668 | B15: =H14 -> 105914 | C15: 18823 | D15: 1068 | E15: 1755 | F15: 0 | G15: 620 | H15: =B15+C15-D15-E15+F15-G15 -> 121294
A16: 45669 | B16: =H15 -> 121294 | C16: 18175 | D16: 3660 | E16: 5935 | F16: 0 | G16: 407 | H16: =B16+C16-D16-E16+F16-G16 -> 129467
A17: 45670 | B17: =H16 -> 129467 | C17: 15879 | D17: 4833 | E17: 2870 | F17: 0 | G17: 368 | H17: =B17+C17-D17-E17+F17-G17 -> 137275
... A34: 45687 | B34: =H33 -> 260126 | C34: 14028 | D34: 5430 | E34: 3419 | F34: 0 | G34: 554 | H34: =B34+C34-D34-E34+F34-G34 -> 264751
A36: MONTHLY TOTALS | C36: =SUM(C5:C34) -> 526622 | D36: =SUM(D5:D34) -> 107831 | E36: =SUM(E5:E34) -> 190170 | G36: =SUM(G5:G34) -> 13870

Sheet 📋 Tax & VAT
A1: 📋 TAX & VAT REPORT
A4: Month | B4: Gross Sales | C4: VATable Sales | D4: VAT Collected (Output Tax) | E4: VAT on Purchases (Input Tax) | F4: VAT Payable | H4: VAT RATE
A5: January | B5: =SUMPRODUCT((TEXT('📊 Sales Report'!$A$5:$A$957,"MMMM")=A5)*'📊 Sales Report'!$I$5:$I$957) -> 4610.06 | C5: =IFERROR(B5/(1+0.12),0) -> 4116.125 | D5: =B5-C5 -> 493.935 | E5: =SUMPRODUCT((TEXT('💸 Expenses'!$A$5:$A$24,"MMMM")=A5)*'💸 Expenses'!$F$5:$F$24)*0.12/1.12 -> 4371.3214 | F5: =D5-E5 -> -3877.3864 | H5: 12%
A6: February | B6: =SUMPRODUCT((TEXT('📊 Sales Report'!$A$5:$A$957,"MMMM")=A6)*'📊 Sales Report'!$I$5:$I$957) -> 3866.912 | C6: =IFERROR(B6/(1+0.12),0) -> 3452.6 | D6: =B6-C6 -> 414.312 | E6: =SUMPRODUCT((TEXT('💸 Expenses'!$A$5:$A$24,"MMMM")=A6)*'💸 Expenses'!$F$5:$F$24)*0.12/1.12 -> 3862.3929 | F6: =D6-E6 -> -3448.0809
A7: March | B7: =SUMPRODUCT((TEXT('📊 Sales Report'!$A$5:$A$957,"MMMM")=A7)*'📊 Sales Report'!$I$5:$I$957) -> 4495.764 | C7: =IFERROR(B7/(1+0.12),0) -> 4014.075 | D7: =B7-C7 -> 481.689 | E7: =SUMPRODUCT((TEXT('💸 Expenses'!$A$5:$A$24,"MMMM")=A7)*'💸 Expenses'!$F$5:$F$24)*0.12/1.12 -> 3926.6786 | F7: =D7-E7 -> -3444.9896
A8: April | B8: =SUMPRODUCT((TEXT('📊 Sales Report'!$A$5:$A$957,"MMMM")=A8)*'📊 Sales Report'!$I$5:$I$957) -> 0 | C8: =IFERROR(B8/(1+0.12),0) -> 0 | D8: =B8-C8 -> 0 | E8: =SUMPRODUCT((TEXT('💸 Expenses'!$A$5:$A$24,"MMMM")=A8)*'💸 Expenses'!$F$5:$F$24)*0.12/1.12 -> 0 | F8: =D8-E8 -> 0
A9: May | B9: =SUMPRODUCT((TEXT('📊 Sales Report'!$A$5:$A$957,"MMMM")=A9)*'📊 Sales Report'!$I$5:$I$957) -> 0 | C9: =IFERROR(B9/(1+0.12),0) -> 0 | D9: =B9-C9 -> 0 | E9: =SUMPRODUCT((TEXT('💸 Expenses'!$A$5:$A$24,"MMMM")=A9)*'💸 Expenses'!$F$5:$F$24)*0.12/1.12 -> 0 | F9: =D9-E9 -> 0
A10: June | B10: =SUMPRODUCT((TEXT('📊 Sales Report'!$A$5:$A$957,"MMMM")=A10)*'📊 Sales Report'!$I$5:$I$957) -> 0 | C10: =IFERROR(B10/(1+0.12),0) -> 0 | D10: =B10-C10 -> 0 | E10: =SUMPRODUCT((TEXT('💸 Expenses'!$A$5:$A$24,"MMMM")=A10)*'💸 Expenses'!$F$5:$F$24)*0.12/1.12 -> 0 | F10: =D10-E10 -> 0
A11: July | B11: =SUMPRODUCT((TEXT('📊 Sales Report'!$A$5:$A$957,"MMMM")=A11)*'📊 Sales Report'!$I$5:$I$957) -> 0 | C11: =IFERROR(B11/(1+0.12),0) -> 0 | D11: =B11-C11 -> 0 | E11: =SUMPRODUCT((TEXT('💸 Expenses'!$A$5:$A$24,"MMMM")=A11)*'💸 Expenses'!$F$5:$F$24)*0.12/1.12 -> 0 | F11: =D11-E11 -> 0
A12: August | B12: =SUMPRODUCT((TEXT('📊 Sales Report'!$A$5:$A$957,"MMMM")=A12)*'📊 Sales Report'!$I$5:$I$957) -> 0 | C12: =IFERROR(B12/(1+0.12),0) -> 0 | D12: =B12-C12 -> 0 | E12: =SUMPRODUCT((TEXT('💸 Expenses'!$A$5:$A$24,"MMMM")=A12)*'💸 Expenses'!$F$5:$F$24)*0.12/1.12 -> 0 | F12: =D12-E12 -> 0
A13: September | B13: =SUMPRODUCT((TEXT('📊 Sales Report'!$A$5:$A$957,"MMMM")=A13)*'📊 Sales Report'!$I$5:$I$957) -> 0 | C13: =IFERROR(B13/(1+0.12),0) -> 0 | D13: =B13-C13 -> 0 | E13: =SUMPRODUCT((TEXT('💸 Expenses'!$A$5:$A$24,"MMMM")=A13)*'💸 Expenses'!$F$5:$F$24)*0.12/1.12 -> 0 | F13: =D13-E13 -> 0
A14: October | B14: =SUMPRODUCT((TEXT('📊 Sales Report'!$A$5:$A$957,"MMMM")=A14)*'📊 Sales Report'!$I$5:$I$957) -> 0 | C14: =IFERROR(B14/(1+0.12),0) -> 0 | D14: =B14-C14 -> 0 | E14: =SUMPRODUCT((TEXT('💸 Expenses'!$A$5:$A$24,"MMMM")=A14)*'💸 Expenses'!$F$5:$F$24)*0.12/1.12 -> 0 | F14: =D14-E14 -> 0
A15: November | B15: =SUMPRODUCT((TEXT('📊 Sales Report'!$A$5:$A$957,"MMMM")=A15)*'📊 Sales Report'!$I$5:$I$957) -> 0 | C15: =IFERROR(B15/(1+0.12),0) -> 0 | D15: =B15-C15 -> 0 | E15: =SUMPRODUCT((TEXT('💸 Expenses'!$A$5:$A$24,"MMMM")=A15)*'💸 Expenses'!$F$5:$F$24)*0.12/1.12 -> 0 | F15: =D15-E15 -> 0
A16: December | B16: =SUMPRODUCT((TEXT('📊 Sales Report'!$A$5:$A$957,"MMMM")=A16)*'📊 Sales Report'!$I$5:$I$957) -> 0 | C16: =IFERROR(B16/(1+0.12),0) -> 0 | D16: =B16-C16 -> 0 | E16: =SUMPRODUCT((TEXT('💸 Expenses'!$A$5:$A$24,"MMMM")=A16)*'💸 Expenses'!$F$5:$F$24)*0.12/1.12 -> 0 | F16: =D16-E16 -> 0
A17: ANNUAL TOTAL | B17: =SUM(B5:B16) -> 12972.736 | C17: =SUM(C5:C16) -> 11582.8 | D17: =SUM(D5:D16) -> 1389.936 | E17: =SUM(E5:E16) -> 12160.393 | F17: =SUM(F5:F16) -> -10770.457

Sheet ⚙ Settings
A1: ⚙ BUSINESS SETTINGS & CONFIGURATION
A4: BUSINESS INFORMATION
B5: Business Name | C5: My Retail Store | D5: ← Edit this value
B6: Address | C6: 123 Main Street, City | D6: ← Edit this value
B7: Phone | C7: +1 800 000 0000 | D7: ← Edit this value
B8: Email | C8: info@mystore.com | D8: ← Edit this value
B9: Tax / Business ID | C9: TIN-000-000-000 | D9: ← Edit this value
B10: Currency Symbol | C10: ₱ | D10: ← Edit this value
A11: FINANCIAL SETTINGS
B12: VAT Rate (%) | C12: 12 | D12: ← Edit this value
B13: Overtime Multiplier | C13: 1.25 | D13: ← Edit this value
B14: Late Penalty/Minute | C14: 10 | D14: ← Edit this value
B15: SSS Deduction | C15: 500 | D15: ← Edit this value
B16: PhilHealth Deduction | C16: 250 | D16: ← Edit this value
B17: Pag-IBIG Deduction | C17: 100 | D17: ← Edit this value
A18: REPORT SETTINGS
B19: Report Start Date | C19: 45658 | D19: ← Edit this value
B20: Report End Date | C20: 46022 | D20: ← Edit this value
B21: Fiscal Year | C21: 2025 | D21: ← Edit this value
B22: Low Stock Threshold | C22: 10 | D22: ← Edit this value
B23: Expiry Warning Days | C23: 30 | D23: ← Edit this value
